[2025-09-26 13:10:21,221] 65 langchain_google_genai.chat_models - WARNING - Retrying langchain_google_genai.chat_models._chat_with_retry.<locals>._chat_with_retry in 2.0 seconds as it raised NotFound: 404 Publisher Model `projects/generativelanguage-ga/locations/us-central1/publishers/google/models/gemini-1.5-flash-002` was not found or your project does not have access to it. Please ensure you are using a valid model version. For more information, see: https://cloud.google.com/vertex-ai/generative-ai/docs/learn/model-versions.
[2025-09-26 13:10:23,609] 65 langchain_google_genai.chat_models - WARNING - Retrying langchain_google_genai.chat_models._chat_with_retry.<locals>._chat_with_retry in 4.0 seconds as it raised NotFound: 404 Publisher Model `projects/generativelanguage-ga/locations/us-central1/publishers/google/models/gemini-1.5-flash-002` was not found or your project does not have access to it. Please ensure you are using a valid model version. For more information, see: https://cloud.google.com/vertex-ai/generative-ai/docs/learn/model-versions.
[2025-09-26 13:10:28,004] 65 langchain_google_genai.chat_models - WARNING - Retrying langchain_google_genai.chat_models._chat_with_retry.<locals>._chat_with_retry in 8.0 seconds as it raised NotFound: 404 Publisher Model `projects/generativelanguage-ga/locations/us-central1/publishers/google/models/gemini-1.5-flash-002` was not found or your project does not have access to it. Please ensure you are using a valid model version. For more information, see: https://cloud.google.com/vertex-ai/generative-ai/docs/learn/model-versions.
[2025-09-26 13:10:36,391] 65 langchain_google_genai.chat_models - WARNING - Retrying langchain_google_genai.chat_models._chat_with_retry.<locals>._chat_with_retry in 16.0 seconds as it raised NotFound: 404 Publisher Model `projects/generativelanguage-ga/locations/us-central1/publishers/google/models/gemini-1.5-flash-002` was not found or your project does not have access to it. Please ensure you are using a valid model version. For more information, see: https://cloud.google.com/vertex-ai/generative-ai/docs/learn/model-versions.
[2025-09-26 13:10:52,775] 65 langchain_google_genai.chat_models - WARNING - Retrying langchain_google_genai.chat_models._chat_with_retry.<locals>._chat_with_retry in 32.0 seconds as it raised NotFound: 404 Publisher Model `projects/generativelanguage-ga/locations/us-central1/publishers/google/models/gemini-1.5-flash-002` was not found or your project does not have access to it. Please ensure you are using a valid model version. For more information, see: https://cloud.google.com/vertex-ai/generative-ai/docs/learn/model-versions.
[2025-09-26 13:11:25,181] 143 root - ERROR - Traceback (most recent call last):
  File "/home/user/gen-ai-portfolio/mcq-generator/StreamlitAPP.py", line 106, in <module>
    response = final_chain.invoke({
               ^^^^^^^^^^^^^^^^^^^^
  File "/home/user/gen-ai-portfolio/.venv/lib/python3.11/site-packages/langchain_core/runnables/base.py", line 3243, in invoke
    input_ = context.run(step.invoke, input_, config, **kwargs)
             ^^^^^^^^^^^^^^^^^^^^^^^^^^^^^^^^^^^^^^^^^^^^^^^^^^
  File "/home/user/gen-ai-portfolio/.venv/lib/python3.11/site-packages/langchain_core/runnables/passthrough.py", line 530, in invoke
    return self._call_with_config(self._invoke, input, config, **kwargs)
           ^^^^^^^^^^^^^^^^^^^^^^^^^^^^^^^^^^^^^^^^^^^^^^^^^^^^^^^^^^^^^
  File "/home/user/gen-ai-portfolio/.venv/lib/python3.11/site-packages/langchain_core/runnables/base.py", line 2089, in _call_with_config
    context.run(
  File "/home/user/gen-ai-portfolio/.venv/lib/python3.11/site-packages/langchain_core/runnables/config.py", line 430, in call_func_with_variable_args
    return func(input, **kwargs)  # type: ignore[call-arg]
           ^^^^^^^^^^^^^^^^^^^^^
  File "/home/user/gen-ai-portfolio/.venv/lib/python3.11/site-packages/langchain_core/runnables/passthrough.py", line 516, in _invoke
    **self.mapper.invoke(
      ^^^^^^^^^^^^^^^^^^^
  File "/home/user/gen-ai-portfolio/.venv/lib/python3.11/site-packages/langchain_core/runnables/base.py", line 4000, in invoke
    output = {key: future.result() for key, future in zip(steps, futures)}
             ^^^^^^^^^^^^^^^^^^^^^^^^^^^^^^^^^^^^^^^^^^^^^^^^^^^^^^^^^^^^^
  File "/home/user/gen-ai-portfolio/.venv/lib/python3.11/site-packages/langchain_core/runnables/base.py", line 4000, in <dictcomp>
    output = {key: future.result() for key, future in zip(steps, futures)}
                   ^^^^^^^^^^^^^^^
  File "/usr/lib/python3.11/concurrent/futures/_base.py", line 456, in result
    return self.__get_result()
           ^^^^^^^^^^^^^^^^^^^
  File "/usr/lib/python3.11/concurrent/futures/_base.py", line 401, in __get_result
    raise self._exception
  File "/usr/lib/python3.11/concurrent/futures/thread.py", line 58, in run
    result = self.fn(*self.args, **self.kwargs)
             ^^^^^^^^^^^^^^^^^^^^^^^^^^^^^^^^^^
  File "/home/user/gen-ai-portfolio/.venv/lib/python3.11/site-packages/langchain_core/runnables/base.py", line 3984, in _invoke_step
    return context.run(
           ^^^^^^^^^^^^
  File "/home/user/gen-ai-portfolio/.venv/lib/python3.11/site-packages/langchain_core/runnables/base.py", line 3245, in invoke
    input_ = context.run(step.invoke, input_, config)
             ^^^^^^^^^^^^^^^^^^^^^^^^^^^^^^^^^^^^^^^^
  File "/home/user/gen-ai-portfolio/.venv/lib/python3.11/site-packages/langchain_google_genai/chat_models.py", line 1676, in invoke
    return super().invoke(input, config, stop=stop, **kwargs)
           ^^^^^^^^^^^^^^^^^^^^^^^^^^^^^^^^^^^^^^^^^^^^^^^^^^
  File "/home/user/gen-ai-portfolio/.venv/lib/python3.11/site-packages/langchain_core/language_models/chat_models.py", line 395, in invoke
    self.generate_prompt(
  File "/home/user/gen-ai-portfolio/.venv/lib/python3.11/site-packages/langchain_core/language_models/chat_models.py", line 1023, in generate_prompt
    return self.generate(prompt_messages, stop=stop, callbacks=callbacks, **kwargs)
           ^^^^^^^^^^^^^^^^^^^^^^^^^^^^^^^^^^^^^^^^^^^^^^^^^^^^^^^^^^^^^^^^^^^^^^^^
  File "/home/user/gen-ai-portfolio/.venv/lib/python3.11/site-packages/langchain_core/language_models/chat_models.py", line 840, in generate
    self._generate_with_cache(
  File "/home/user/gen-ai-portfolio/.venv/lib/python3.11/site-packages/langchain_core/language_models/chat_models.py", line 1089, in _generate_with_cache
    result = self._generate(
             ^^^^^^^^^^^^^^^
  File "/home/user/gen-ai-portfolio/.venv/lib/python3.11/site-packages/langchain_google_genai/chat_models.py", line 1790, in _generate
    response: GenerateContentResponse = _chat_with_retry(
                                        ^^^^^^^^^^^^^^^^^
  File "/home/user/gen-ai-portfolio/.venv/lib/python3.11/site-packages/langchain_google_genai/chat_models.py", line 238, in _chat_with_retry
    return _chat_with_retry(**params)
           ^^^^^^^^^^^^^^^^^^^^^^^^^^
  File "/home/user/gen-ai-portfolio/.venv/lib/python3.11/site-packages/tenacity/__init__.py", line 338, in wrapped_f
    return copy(f, *args, **kw)
           ^^^^^^^^^^^^^^^^^^^^
  File "/home/user/gen-ai-portfolio/.venv/lib/python3.11/site-packages/tenacity/__init__.py", line 477, in __call__
    do = self.iter(retry_state=retry_state)
         ^^^^^^^^^^^^^^^^^^^^^^^^^^^^^^^^^^
  File "/home/user/gen-ai-portfolio/.venv/lib/python3.11/site-packages/tenacity/__init__.py", line 378, in iter
    result = action(retry_state)
             ^^^^^^^^^^^^^^^^^^^
  File "/home/user/gen-ai-portfolio/.venv/lib/python3.11/site-packages/tenacity/__init__.py", line 420, in exc_check
    raise retry_exc.reraise()
          ^^^^^^^^^^^^^^^^^^^
  File "/home/user/gen-ai-portfolio/.venv/lib/python3.11/site-packages/tenacity/__init__.py", line 187, in reraise
    raise self.last_attempt.result()
          ^^^^^^^^^^^^^^^^^^^^^^^^^^
  File "/usr/lib/python3.11/concurrent/futures/_base.py", line 449, in result
    return self.__get_result()
           ^^^^^^^^^^^^^^^^^^^
  File "/usr/lib/python3.11/concurrent/futures/_base.py", line 401, in __get_result
    raise self._exception
  File "/home/user/gen-ai-portfolio/.venv/lib/python3.11/site-packages/tenacity/__init__.py", line 480, in __call__
    result = fn(*args, **kwargs)
             ^^^^^^^^^^^^^^^^^^^
  File "/home/user/gen-ai-portfolio/.venv/lib/python3.11/site-packages/langchain_google_genai/chat_models.py", line 208, in _chat_with_retry
    return generation_method(**kwargs)
           ^^^^^^^^^^^^^^^^^^^^^^^^^^^
  File "/home/user/gen-ai-portfolio/.venv/lib/python3.11/site-packages/google/ai/generativelanguage_v1beta/services/generative_service/client.py", line 869, in generate_content
    response = rpc(
               ^^^^
  File "/home/user/gen-ai-portfolio/.venv/lib/python3.11/site-packages/google/api_core/gapic_v1/method.py", line 131, in __call__
    return wrapped_func(*args, **kwargs)
           ^^^^^^^^^^^^^^^^^^^^^^^^^^^^^
  File "/home/user/gen-ai-portfolio/.venv/lib/python3.11/site-packages/google/api_core/retry/retry_unary.py", line 294, in retry_wrapped_func
    return retry_target(
           ^^^^^^^^^^^^^
  File "/home/user/gen-ai-portfolio/.venv/lib/python3.11/site-packages/google/api_core/retry/retry_unary.py", line 156, in retry_target
    next_sleep = _retry_error_helper(
                 ^^^^^^^^^^^^^^^^^^^^
  File "/home/user/gen-ai-portfolio/.venv/lib/python3.11/site-packages/google/api_core/retry/retry_base.py", line 214, in _retry_error_helper
    raise final_exc from source_exc
  File "/home/user/gen-ai-portfolio/.venv/lib/python3.11/site-packages/google/api_core/retry/retry_unary.py", line 147, in retry_target
    result = target()
             ^^^^^^^^
  File "/home/user/gen-ai-portfolio/.venv/lib/python3.11/site-packages/google/api_core/timeout.py", line 130, in func_with_timeout
    return func(*args, **kwargs)
           ^^^^^^^^^^^^^^^^^^^^^
  File "/home/user/gen-ai-portfolio/.venv/lib/python3.11/site-packages/google/api_core/grpc_helpers.py", line 78, in error_remapped_callable
    raise exceptions.from_grpc_error(exc) from exc
google.api_core.exceptions.NotFound: 404 Publisher Model `projects/generativelanguage-ga/locations/us-central1/publishers/google/models/gemini-1.5-flash-002` was not found or your project does not have access to it. Please ensure you are using a valid model version. For more information, see: https://cloud.google.com/vertex-ai/generative-ai/docs/learn/model-versions

